I'm sorry, but an uncaught exception occurred.

While running game code:
  File "game/events.rpy", line 37, in script
    kngiht "The prophecy chose us for a reason, and the Chosen Witch will lead us. We can trust [p_object]."
Exception: Sayer 'kngiht' is not defined.

-- Full Traceback ------------------------------------------------------------

Full traceback:
  File "game/events.rpy", line 37, in script
    kngiht "The prophecy chose us for a reason, and the Chosen Witch will lead us. We can trust [p_object]."
  File "C:\Users\Emily Lin\Downloads\renpy-8.3.4-sdk\renpy\ast.py", line 2579, in execute
    Say.execute(self)
  File "C:\Users\Emily Lin\Downloads\renpy-8.3.4-sdk\renpy\ast.py", line 581, in execute
    who = eval_who(self.who, self.who_fast)
  File "C:\Users\Emily Lin\Downloads\renpy-8.3.4-sdk\renpy\ast.py", line 470, in eval_who
    raise Exception("Sayer '%s' is not defined." % who)
Exception: Sayer 'kngiht' is not defined.

Windows-10-10.0.19045 AMD64
Ren'Py 8.3.4.24120703
Forever Yours, The Devil 1.0
Sun Jan 19 14:26:34 2025
